[32m2025-01-21 01:18:44 +0800[0m - dagster - [34mDEBUG[0m - __ASSET_JOB - 7cd9107b-756f-4460-ad7b-381d9395ab5d - 91545 - LOGS_CAPTURED - Started capturing logs in process (pid: 91545).
[32m2025-01-21 01:18:44 +0800[0m - dagster - [34mDEBUG[0m - __ASSET_JOB - 7cd9107b-756f-4460-ad7b-381d9395ab5d - 91545 - load_airquality_data - STEP_START - Started execution of step "load_airquality_data".
[32m2025-01-21 01:18:44 +0800[0m - dagster - [34mERROR[0m - [31m__ASSET_JOB - 7cd9107b-756f-4460-ad7b-381d9395ab5d - 91545 - load_airquality_data - STEP_FAILURE - Execution of step "load_airquality_data" failed.

dagster._core.errors.DagsterExecutionStepExecutionError: Error occurred while executing op "load_airquality_data"::

FileNotFoundError: data/03_Gold/01_Dev/AirQualityUCI.csv does not exist

Stack Trace:
  File "/Users/jamesballesteros/miniforge3/envs/dagster/lib/python3.12/site-packages/dagster/_core/execution/plan/utils.py", line 55, in op_execution_error_boundary
    yield
  File "/Users/jamesballesteros/miniforge3/envs/dagster/lib/python3.12/site-packages/dagster/_utils/__init__.py", line 480, in iterate_with_context
    next_output = next(iterator)
                  ^^^^^^^^^^^^^^
  File "/Users/jamesballesteros/miniforge3/envs/dagster/lib/python3.12/site-packages/dagster/_core/execution/plan/compute_generator.py", line 127, in _coerce_op_compute_fn_to_iterator
    result = invoke_compute_fn(
             ^^^^^^^^^^^^^^^^^^
  File "/Users/jamesballesteros/miniforge3/envs/dagster/lib/python3.12/site-packages/dagster/_core/execution/plan/compute_generator.py", line 115, in invoke_compute_fn
    return fn(context, **args_to_pass) if context_arg_provided else fn(**args_to_pass)
                                                                    ^^^^^^^^^^^^^^^^^^
  File "/Users/jamesballesteros/MLOPS/MLOPS_HW1/src/assets.py", line 36, in load_airquality_data
    raise FileNotFoundError(f"{file_path} does not exist")
[0m
